Workbook
Name Cst_Médio_Lingote: Dados!$Q$2
Name CstMedKgFund: Dados!$N$4
Name CstOleoKgALuminio: Dados!$I$8
Name CustoOleoFornada: Dados!$I$7
Name Dias_Uteis: Dados!$Q$5
Name OleoKGAluminio: Dados!$I$4
Name Produto: Tabela2[Cód Placa - Descrição]
Name Produto: Tabela2[Cód Placa - Descrição]
Name Profissional: Tabela1[Nome]
Name Profissional: Tabela1[Nome]

Sheet Dados
A1: CUSTO MÉDIO | F1: CONSUMO OLEO / KG DE ALUMINIO | K1: Custo Médio Alumínio Fundido | P1: Tipo | Q1: Valor
A2: Descrição | B2: Qtde Total Compra | C2: Valor Total | D2: Custo Médio | F2: Total Aluminio | I2: =CmpLingote[[#Totals],[Qtde Aluminio]]+CmpSucata[[#Totals],[Qtde Aluminio]] -> 73689.1 | K2: Compras Total | N2: =Tabela8[[#Totals],[Valor Total]] -> 1039745.6 | P2: Lingote | Q2: =(VLOOKUP(TODAY(),CmpLingote[],3,TRUE))*1.1 -> 17.6
A3: Lingote | B3: =CmpLingote[[#Totals],[Qtde Aluminio]] -> 20524.8 | C3: =CmpLingote[[#Totals],[Total]] -> 400378.85 | D3: =Tabela8[[#This Row],[Valor Total]]/(Tabela8[[#This Row],[Qtde Total Compra]]*0.9) -> 21.67453 | F3: Total Oleo | I3: =CompraOleo[[#Totals],[QTDE OLEO]] -> 34101 | K3: Peso Aluminio Util | N3: =Tabela8[[#This Row],[Qtde Total Compra]]*0.9+B4*0.65 -> 53029.115 | P3: Sucata | Q3: =(VLOOKUP(TODAY(),CmpSucata[],3,TRUE))*1.3 -> 15.6
A4: Sucata | B4: =CmpSucata[[#Totals],[Qtde Aluminio]] -> 53164.3 | C4: =CmpSucata[[#Totals],[Total]] -> 542763.24 | D4: =Tabela8[[#This Row],[Valor Total]]/(Tabela8[[#This Row],[Qtde Total Compra]]*0.7) -> 14.584525 | F4: Cada Litro de Oleo Funde (KG Alum.) | I4: =I2/I3*1.1 -> 2.376998 | K4: Custo Médio/Kg Fundido | N4: =N2/N3 -> 19.60707 | P4: Mistura | Q4: =GEOMEAN(Q2:Q3) -> 16.569852
A5: Oleo | B5: =CompraOleo[[#Totals],[QTDE OLEO]] -> 34101 | C5: =CompraOleo[[#Totals],[Total]] -> 85252.5 | D5: =Tabela8[[#This Row],[Valor Total]]/(Tabela8[[#This Row],[Qtde Total Compra]]*0.95) -> 2.6315789 | F5: Capacidade do Fornada KG | I5: 180 | P5: Dias Uteis | Q5: 22
A6: Insumos | C6: =CompraInsumos[[#Totals],[Total]] -> 11351 | F6: Qtde Oléo/Fornada | I6: =I5/I4 -> 75.725767 | K6: Custo Lingote | N6: =CmpLingote[[#Totals],[Total]]/(CmpLingote[[#Totals],[Qtde Aluminio]]*0.9) -> 21.67453
A7: TOTAL | C7: =SUBTOTAL(109,Tabela8[Valor Total]) -> 1039745.6 | F7: Custo Oleo/Fornada | I7: =I6*D5 -> 199.27833 | K7: Custo Sucata | N7: =CmpSucata[[#Totals],[Total]]/(CmpSucata[[#Totals],[Qtde Aluminio]]*0.65) -> 15.706411
F8: Custo Oleo / Kg Fundido | I8: =I7/I5 -> 1.1071019
A11: COMPRAS LINGOTE | F11: COMPRAS SUCATA | K11: COMPRAS OLEO | P11: COMPRAS INSUMOS | S11: Custo Machos Kg
A12: Data | B12: Qtde Aluminio | C12: Custo/Kg Alumínio | D12: Total | F12: Data | G12: Qtde Aluminio | H12: Custo/Kg Alumínio | I12: Total | K12: Data | L12: QTDE OLEO | M12: CUSTO / L | N12: Total | P12: Data | Q12: Total | S12: Data | T12: Total
A13: 45688 | B13: 6675.3 | C13: 16 | D13: 192328.4 | F13: 45838 | G13: 20717.5 | H13: 10 | I13: 206393.59 | K13: 45658 | L13: 1 | M13: 2.5 | N13: =CompraOleo[[#This Row],[CUSTO / L]]*CompraOleo[[#This Row],[QTDE OLEO]] -> 2.5 | P13: 45838 | Q13: 3417.5 | S13: 45658 | T13: 1.5
A14: 45930 | B14: 3804.5 | C14: 16 | D14: 56786.15 | F14: 46295 | G14: 15683.8 | H14: 10 | I14: 155365.15 | K14: 45838 | L14: 11900 | M14: 2.5 | N14: =CompraOleo[[#This Row],[CUSTO / L]]*CompraOleo[[#This Row],[QTDE OLEO]] -> 29750 | P14: 45930 | Q14: 3042.5 | S14: 45748 | T14: 1.5
A15: 45991 | B15: 1035 | C15: 14.7 | D15: =CmpLingote[[#This Row],[Custo/Kg Alumínio]]*CmpLingote[[#This Row],[Qtde Aluminio]] -> 15214.5 | F15: 45961 | G15: 3486 | H15: 10 | I15: =CmpSucata[[#This Row],[Custo/Kg Alumínio]]*CmpSucata[[#This Row],[Qtde Aluminio]] -> 34860 | K15: 45930 | L15: 7000 | M15: 2.5 | N15: =CompraOleo[[#This Row],[CUSTO / L]]*CompraOleo[[#This Row],[QTDE OLEO]] -> 17500 | P15: 45961 | Q15: 1305 | S15: 45778 | T15: 1.5
A16: 46022 | B16: 1003 | C16: 14.7 | D16: =CmpLingote[[#This Row],[Custo/Kg Alumínio]]*CmpLingote[[#This Row],[Qtde Aluminio]] -> 14744.1 | F16: 45991 | G16: 3558 | H16: 10 | I16: =CmpSucata[[#This Row],[Qtde Aluminio]]*CmpSucata[[#This Row],[Custo/Kg Alumínio]] -> 35580 | K16: 45961 | L16: 2000 | M16: 2.5 | N16: =CompraOleo[[#This Row],[CUSTO / L]]*CompraOleo[[#This Row],[QTDE OLEO]] -> 5000 | P16: 45991 | Q16: 386 | S16: 45809 | T16: 1.7
A17: 46053 | B17: 1001 | C17: 14.7 | D17: =CmpLingote[[#This Row],[Custo/Kg Alumínio]]*CmpLingote[[#This Row],[Qtde Aluminio]] -> 14714.7 | F17: 46022 | G17: 887 | H17: 10 | I17: =CmpSucata[[#This Row],[Custo/Kg Alumínio]]*CmpSucata[[#This Row],[Qtde Aluminio]] -> 8870 | K17: 45991 | L17: 2000 | M17: 2.5 | N17: =CompraOleo[[#This Row],[CUSTO / L]]*CompraOleo[[#This Row],[QTDE OLEO]] -> 5000 | P17: 46022 | Q17: 305
A18: 46063 | B18: 1000 | C18: 15 | D18: =CmpLingote[[#This Row],[Custo/Kg Alumínio]]*CmpLingote[[#This Row],[Qtde Aluminio]] -> 15000 | F18: 46053 | G18: 2357.5 | H18: 12 | I18: =CmpSucata[[#This Row],[Custo/Kg Alumínio]]*CmpSucata[[#This Row],[Qtde Aluminio]] -> 28290 | K18: 46022 | L18: 1000 | M18: 2.5 | N18: =CompraOleo[[#This Row],[CUSTO / L]]*CompraOleo[[#This Row],[QTDE OLEO]] -> 2500 | P18: 46053 | Q18: =500+295 -> 795
A19: 46083 | B19: 1004 | C19: 15 | D19: =CmpLingote[[#This Row],[Custo/Kg Alumínio]]*CmpLingote[[#This Row],[Qtde Aluminio]] -> 15060 | F19: 46066 | G19: =600+474+427 -> 1501 | H19: 11 | I19: =CmpSucata[[#This Row],[Custo/Kg Alumínio]]*CmpSucata[[#This Row],[Qtde Aluminio]] -> 16511 | K19: 46053 | L19: 1000 | M19: 2.5 | N19: =CompraOleo[[#This Row],[CUSTO / L]]*CompraOleo[[#This Row],[QTDE OLEO]] -> 2500 | P19: 46081 | Q19: 500
A20: 46098 | B20: 1000 | C20: 15 | D20: =CmpLingote[[#This Row],[Custo/Kg Alumínio]]*CmpLingote[[#This Row],[Qtde Aluminio]] -> 15000 | F20: 46085 | G20: 606 | H20: 10 | I20: =CmpSucata[[#This Row],[Custo/Kg Alumínio]]*CmpSucata[[#This Row],[Qtde Aluminio]] -> 6060 | K20: 46056 | L20: 1000 | M20: 2.5 | N20: =CompraOleo[[#This Row],[CUSTO / L]]*CompraOleo[[#This Row],[QTDE OLEO]] -> 2500 | P20: 46112 | Q20: 500
A21: 46106 | B21: 1001 | C21: 15 | D21: =CmpLingote[[#This Row],[Custo/Kg Alumínio]]*CmpLingote[[#This Row],[Qtde Aluminio]] -> 15015 | F21: 46090 | G21: 547 | H21: 10 | I21: =CmpSucata[[#This Row],[Custo/Kg Alumínio]]*CmpSucata[[#This Row],[Qtde Aluminio]] -> 5470 | K21: 46076 | L21: 1000 | M21: 2.5 | N21: =CompraOleo[[#This Row],[CUSTO / L]]*CompraOleo[[#This Row],[QTDE OLEO]] -> 2500 | P21: 46142 | Q21: 600
A22: 46133 | B22: 1000 | C22: 15 | D22: =CmpLingote[[#This Row],[Custo/Kg Alumínio]]*CmpLingote[[#This Row],[Qtde Aluminio]] -> 15000 | F22: 46092 | G22: 816.5 | H22: 12 | I22: =CmpSucata[[#This Row],[Custo/Kg Alumínio]]*CmpSucata[[#This Row],[Qtde Aluminio]] -> 9798 | K22: 46085 | L22: 1000 | M22: 2.5 | N22: =CompraOleo[[#This Row],[CUSTO / L]]*CompraOleo[[#This Row],[QTDE OLEO]] -> 2500 | P22: 46172 | Q22: 500
A23: 46141 | B23: 1000 | C23: 15.5 | D23: =CmpLingote[[#This Row],[Custo/Kg Alumínio]]*CmpLingote[[#This Row],[Qtde Aluminio]] -> 15500 | F23: 46099 | G23: 96.5 | H23: 7 | I23: =CmpSucata[[#This Row],[Custo/Kg Alumínio]]*CmpSucata[[#This Row],[Qtde Aluminio]] -> 675.5 | K23: 46094 | L23: 1000 | M23: 2.5 | N23: =CompraOleo[[#This Row],[CUSTO / L]]*CompraOleo[[#This Row],[QTDE OLEO]] -> 2500
A24: 46161 | B24: 1001 | C24: 16 | D24: =CmpLingote[[#This Row],[Custo/Kg Alumínio]]*CmpLingote[[#This Row],[Qtde Aluminio]] -> 16016 | F24: 46122 | G24: 1607 | H24: 12 | I24: =CmpSucata[[#This Row],[Custo/Kg Alumínio]]*CmpSucata[[#This Row],[Qtde Aluminio]] -> 19284 | K24: 46106 | L24: 1000 | M24: 2.5 | N24: =CompraOleo[[#This Row],[CUSTO / L]]*CompraOleo[[#This Row],[QTDE OLEO]] -> 2500
D25: =CmpLingote[[#This Row],[Custo/Kg Alumínio]]*CmpLingote[[#This Row],[Qtde Aluminio]] -> 0 | F25: 46149 | G25: 710 | H25: 12 | I25: =CmpSucata[[#This Row],[Custo/Kg Alumínio]]*CmpSucata[[#This Row],[Qtde Aluminio]] -> 8520 | K25: 46114 | L25: 1000 | M25: 2.5 | N25: =CompraOleo[[#This Row],[CUSTO / L]]*CompraOleo[[#This Row],[QTDE OLEO]] -> 2500
D26: =CmpLingote[[#This Row],[Custo/Kg Alumínio]]*CmpLingote[[#This Row],[Qtde Aluminio]] -> 0 | F26: 46161 | G26: 590.5 | H26: 12 | I26: =CmpSucata[[#This Row],[Custo/Kg Alumínio]]*CmpSucata[[#This Row],[Qtde Aluminio]] -> 7086 | K26: 46122 | L26: 800 | M26: 2.5 | N26: =CompraOleo[[#This Row],[CUSTO / L]]*CompraOleo[[#This Row],[QTDE OLEO]] -> 2000 | T26: =SUBTOTAL(101,Tabela461213[Total]) -> 1.55
D27: =CmpLingote[[#This Row],[Custo/Kg Alumínio]]*CmpLingote[[#This Row],[Qtde Aluminio]] -> 0 | K27: 46133 | L27: 800 | M27: 2.5 | N27: =CompraOleo[[#This Row],[CUSTO / L]]*CompraOleo[[#This Row],[QTDE OLEO]] -> 2000 | Q27: =SUBTOTAL(109,CompraInsumos[Total]) -> 11351
D28: =CmpLingote[[#This Row],[Custo/Kg Alumínio]]*CmpLingote[[#This Row],[Qtde Aluminio]] -> 0 | K28: 46149 | L28: 800 | M28: 2.5 | N28: =CompraOleo[[#This Row],[CUSTO / L]]*CompraOleo[[#This Row],[QTDE OLEO]] -> 2000
K29: 46160 | L29: 800 | M29: 2.5 | N29: =CompraOleo[[#This Row],[CUSTO / L]]*CompraOleo[[#This Row],[QTDE OLEO]] -> 2000
B33: =SUBTOTAL(109,CmpLingote[Qtde Aluminio]) -> 20524.8 | D33: =SUBTOTAL(109,CmpLingote[Total]) -> 400378.85 | G33: =SUBTOTAL(109,CmpSucata[Qtde Aluminio]) -> 53164.3 | I33: =SUBTOTAL(109,CmpSucata[Total]) -> 542763.24 | L33: =SUBTOTAL(109,CompraOleo[QTDE OLEO]) -> 34101 | M33: =SUBTOTAL(101,CompraOleo[CUSTO / L]) -> 2.5 | N33: =SUBTOTAL(109,CompraOleo[Total]) -> 85252.5

Sheet Profissionais
A1: Nome | B1: Função | C1: Salário | D1: Cartão | E1: Custo/h
A2: Marcelo Santos | B2: Moldador | C2: 2968 | D2: 500 | E2: =(Tabela1[[#This Row],[Salário]]*1.45+Tabela1[[#This Row],[Cartão]])/180*1.05 -> 28.021 | J2: Moldador | K2: 30.26
A3: Daniel Garcia | B3: Moldador | C3: 2968 | D3: 500 | E3: =(Tabela1[[#This Row],[Salário]]*1.45+Tabela1[[#This Row],[Cartão]])/180*1.05 -> 28.021 | J3: Moldador | K3: 30.26
A4: Claudio Henrique | B4: Ajudante | C4: 2236.6 | D4: 280 | E4: =(Tabela1[[#This Row],[Salário]]*1.45+Tabela1[[#This Row],[Cartão]])/180*1.05 -> 20.551242 | J4: Ajudante | K4: 23
A5: Anderson | B5: Ajudante | C5: 2236.6 | D5: 280 | E5: =(Tabela1[[#This Row],[Salário]]*1.45+Tabela1[[#This Row],[Cartão]])/180*1.05 -> 20.551242 | J5: Ajudante | K5: 23
A6: Renan Gabriel | B6: Ajudante | C6: 2236.6 | D6: 280 | E6: =(Tabela1[[#This Row],[Salário]]*1.45+Tabela1[[#This Row],[Cartão]])/180*1.05 -> 20.551242 | J6: Rebarbador | K6: 23
A7: Victor Hugo | B7: Ajudante | C7: 2236.6 | D7: 280 | E7: =(Tabela1[[#This Row],[Salário]]*1.45+Tabela1[[#This Row],[Cartão]])/180*1.05 -> 20.551242
A8: William | B8: Forno | C8: 2968 | D8: 500 | E8: =(Tabela1[[#This Row],[Salário]]*1.45+Tabela1[[#This Row],[Cartão]])/180*1.05 -> 28.021 | J8: Acabamento | K8: 46
A9: João Paulo | B9: Ajudante | C9: 2236.6 | D9: 280 | E9: =(Tabela1[[#This Row],[Salário]]*1.45+Tabela1[[#This Row],[Cartão]])/180*1.05 -> 20.551242
A10: Marco W | B10: Ajudante | C10: 2236.6 | D10: 280 | E10: =(Tabela1[[#This Row],[Salário]]*1.45+Tabela1[[#This Row],[Cartão]])/180*1.05 -> 20.551242
A11: Marlon | B11: Ajudante | C11: 2236.6 | D11: 280 | E11: =(Tabela1[[#This Row],[Salário]]*1.45+Tabela1[[#This Row],[Cartão]])/180*1.05 -> 20.551242

Sheet Produtos
A1: Cód Placa - Descrição | B1: Qdt Peça Placa | C1: Peso Pç | D1: Peso Total Galho | E1: Retorno | F1: Peso Caixa Areia | G1: Qde macho / CX | H1: Peso Macho | I1: Caixa Usada | J1: Cód Cx Macho | K1: Cód Placa | L1: Tipo de Material | M1: Prço/Kg | N1: Cliente | O1: Usinagem Pintura Outros
A2: 276003 Flange Distribuidor De Ar / REGULADOR 26002 - Fundido | B2: 2 | D2: 0 | E2: =((Tabela2[[#This Row],[Peso Total Galho]]-(Tabela2[[#This Row],[Peso Pç]]*Tabela2[[#This Row],[Qdt Peça Placa]]))*0.9) -> 0 | L2: Sucata | M2: =VLOOKUP(Tabela2[[#This Row],[Tipo de Material]],Dados!$P$2:$Q$4,2,FALSE) -> 15.6 | N2: Jumil | O2: 3
A3: 2766811 POLIA FUNDIDO | B3: 1 | C3: 1.885 | D3: 3.335 | E3: =((Tabela2[[#This Row],[Peso Total Galho]]-(Tabela2[[#This Row],[Peso Pç]]*Tabela2[[#This Row],[Qdt Peça Placa]]))*0.9) -> 1.305 | L3: Sucata | M3: =VLOOKUP(Tabela2[[#This Row],[Tipo de Material]],Dados!$P$2:$Q$4,2,FALSE) -> 15.6 | N3: Jumil | O3: 4
A4: Corpo Visor Agua / Luz Fundido | B4: 2 | C4: 0.444 | D4: 1.452 | E4: =((Tabela2[[#This Row],[Peso Total Galho]]-(Tabela2[[#This Row],[Peso Pç]]*Tabela2[[#This Row],[Qdt Peça Placa]]))*0.9) -> 0.5076 | L4: Sucata | M4: =VLOOKUP(Tabela2[[#This Row],[Tipo de Material]],Dados!$P$2:$Q$4,2,FALSE) -> 15.6 | N4: Senun | O4: 5
A5: PROTEC TITAN 150 ES | B5: 1 | C5: 1.2 | D5: 1.85 | E5: =((Tabela2[[#This Row],[Peso Total Galho]]-(Tabela2[[#This Row],[Peso Pç]]*Tabela2[[#This Row],[Qdt Peça Placa]]))*0.9) -> 0.585 | L5: Lingote | M5: =VLOOKUP(Tabela2[[#This Row],[Tipo de Material]],Dados!$P$2:$Q$4,2,FALSE) -> 17.6 | N5: Protec
A6: 0429005 TAMPA DO DISTRIBUIDOR (0432527P) | B6: 1 | C6: 2.99 | D6: 5.29 | E6: =((Tabela2[[#This Row],[Peso Total Galho]]-(Tabela2[[#This Row],[Peso Pç]]*Tabela2[[#This Row],[Qdt Peça Placa]]))*0.9) -> 2.07 | G6: 1 | H6: 2 | J6: 400411 | L6: Sucata | M6: =VLOOKUP(Tabela2[[#This Row],[Tipo de Material]],Dados!$P$2:$Q$4,2,FALSE) -> 15.6 | N6: Jumil | O6: 1
A7: 0429011 ARO | B7: 1 | C7: 1 | D7: 1.8 | E7: =((Tabela2[[#This Row],[Peso Total Galho]]-(Tabela2[[#This Row],[Peso Pç]]*Tabela2[[#This Row],[Qdt Peça Placa]]))*0.9) -> 0.72 | L7: Sucata | M7: =VLOOKUP(Tabela2[[#This Row],[Tipo de Material]],Dados!$P$2:$Q$4,2,FALSE) -> 15.6 | N7: Jumil | O7: 4
A8: 0429013 BICA DUPLA (0432155P) | B8: 4 | C8: 0.185 | D8: 1.308 | E8: =((Tabela2[[#This Row],[Peso Total Galho]]-(Tabela2[[#This Row],[Peso Pç]]*Tabela2[[#This Row],[Qdt Peça Placa]]))*0.9) -> 0.5112 | G8: 4 | H8: 0.175 | J8: 400420 | L8: Sucata | M8: =VLOOKUP(Tabela2[[#This Row],[Tipo de Material]],Dados!$P$2:$Q$4,2,FALSE) -> 15.6 | N8: Jumil | O8: 1
A9: 0460277 TAMPA DO DISTRIBUIDOR (0460276P) | B9: 1 | C9: 1.8 | D9: 2 | E9: =((Tabela2[[#This Row],[Peso Total Galho]]-(Tabela2[[#This Row],[Peso Pç]]*Tabela2[[#This Row],[Qdt Peça Placa]]))*0.9) -> 0.18 | G9: 1 | H9: 2.03 | J9: 400421 | L9: Sucata | M9: =VLOOKUP(Tabela2[[#This Row],[Tipo de Material]],Dados!$P$2:$Q$4,2,FALSE) -> 15.6 | N9: Jumil | O9: 15
A10: 2760002 Regulador (3225354P) Fundido | B10: 4 | C10: 0.218 | D10: 1.544 | E10: =((Tabela2[[#This Row],[Peso Total Galho]]-(Tabela2[[#This Row],[Peso Pç]]*Tabela2[[#This Row],[Qdt Peça Placa]]))*0.9) -> 0.6048 | L10: Sucata | M10: =VLOOKUP(Tabela2[[#This Row],[Tipo de Material]],Dados!$P$2:$Q$4,2,FALSE) -> 15.6 | N10: Jumil | O10: 3
A11: 2760173 Base Do Condutor Da Semente (2749842P) Fundido | B11: 2 | C11: 1.15 | D11: 4.06 | E11: =((Tabela2[[#This Row],[Peso Total Galho]]-(Tabela2[[#This Row],[Peso Pç]]*Tabela2[[#This Row],[Qdt Peça Placa]]))*0.9) -> 1.584 | L11: Sucata | M11: =VLOOKUP(Tabela2[[#This Row],[Tipo de Material]],Dados!$P$2:$Q$4,2,FALSE) -> 15.6 | N11: Jumil | O11: 8
A12: 2760174 Condutor Inclinado (2749843P) Fundido | B12: 2 | C12: 0.737 | D12: 2.608 | E12: =((Tabela2[[#This Row],[Peso Total Galho]]-(Tabela2[[#This Row],[Peso Pç]]*Tabela2[[#This Row],[Qdt Peça Placa]]))*0.9) -> 1.0206 | G12: 2 | H12: 0.49 | J12: 400418/01 | L12: Sucata | M12: =VLOOKUP(Tabela2[[#This Row],[Tipo de Material]],Dados!$P$2:$Q$4,2,FALSE) -> 15.6 | N12: Jumil | O12: 1
A13: 2760211 Tapo Deposito Unico De Sementes (2749147P) Fundido | D13: 0 | E13: =((Tabela2[[#This Row],[Peso Total Galho]]-(Tabela2[[#This Row],[Peso Pç]]*Tabela2[[#This Row],[Qdt Peça Placa]]))*0.9) -> 0 | L13: Sucata | M13: =VLOOKUP(Tabela2[[#This Row],[Tipo de Material]],Dados!$P$2:$Q$4,2,FALSE) -> 15.6 | N13: Jumil | O13: 8
A14: 2760315 Base do Depósito (2729990P) - FUNDIDO | B14: 4 | C14: 0.784 | D14: 5.548 | E14: =((Tabela2[[#This Row],[Peso Total Galho]]-(Tabela2[[#This Row],[Peso Pç]]*Tabela2[[#This Row],[Qdt Peça Placa]]))*0.9) -> 2.1708 | G14: 12 | H14: 2.662 | J14: 400403 | L14: Sucata | M14: =VLOOKUP(Tabela2[[#This Row],[Tipo de Material]],Dados!$P$2:$Q$4,2,FALSE) -> 15.6 | N14: Jumil | O14: 8
A15: 2766824 Distribuidor de Ar 12s - FUNDIDO | B15: 1 | C15: 2.47 | D15: 1.8 | E15: =((Tabela2[[#This Row],[Peso Total Galho]]-(Tabela2[[#This Row],[Peso Pç]]*Tabela2[[#This Row],[Qdt Peça Placa]]))*0.9) -> -0.603 | G15: 1 | H15: 3.006 | J15: 400417 | L15: Sucata | M15: =VLOOKUP(Tabela2[[#This Row],[Tipo de Material]],Dados!$P$2:$Q$4,2,FALSE) -> 15.6 | N15: Jumil | O15: 4
A16: 9990066 - Marcação luva 3,5x7 / 4x7 / 5x4 / Bacia - Fundido | B16: 3 | C16: 0.412 | D16: 3.036 | E16: =((Tabela2[[#This Row],[Peso Total Galho]]-(Tabela2[[#This Row],[Peso Pç]]*Tabela2[[#This Row],[Qdt Peça Placa]]))*0.9) -> 1.62 | L16: Lingote | M16: =VLOOKUP(Tabela2[[#This Row],[Tipo de Material]],Dados!$P$2:$Q$4,2,FALSE) -> 17.6 | N16: Oscar | O16: 4
A17: 9990066 - Varão 1 / 2 / 3 / 4 - Fundido | B17: 4 | C17: 0.412 | D17: 4.048 | E17: =((Tabela2[[#This Row],[Peso Total Galho]]-(Tabela2[[#This Row],[Peso Pç]]*Tabela2[[#This Row],[Qdt Peça Placa]]))*0.9) -> 2.16 | L17: Lingote | M17: =VLOOKUP(Tabela2[[#This Row],[Tipo de Material]],Dados!$P$2:$Q$4,2,FALSE) -> 17.6 | N17: Oscar | O17: 4
A18: Acoplador 2750340 - FUNDIDO | B18: 3 | C18: 0.884 | D18: 4.692 | E18: =((Tabela2[[#This Row],[Peso Total Galho]]-(Tabela2[[#This Row],[Peso Pç]]*Tabela2[[#This Row],[Qdt Peça Placa]]))*0.9) -> 1.836 | G18: 9 | H18: 1.401 | J18: 400401 | L18: Sucata | M18: =VLOOKUP(Tabela2[[#This Row],[Tipo de Material]],Dados!$P$2:$Q$4,2,FALSE) -> 15.6 | N18: Jumil | O18: 10
A19: ACOPLADOR DO PRATO - DANILO | B19: 1 | C19: 1.1 | D19: 1.6 | E19: =((Tabela2[[#This Row],[Peso Total Galho]]-(Tabela2[[#This Row],[Peso Pç]]*Tabela2[[#This Row],[Qdt Peça Placa]]))*0.9) -> 0.45 | L19: Lingote | M19: =VLOOKUP(Tabela2[[#This Row],[Tipo de Material]],Dados!$P$2:$Q$4,2,FALSE) -> 17.6 | N19: Danilo
A20: ADAPTADOR 0429051 | B20: 22 | C20: 0.024 | D20: 1.65 | E20: =((Tabela2[[#This Row],[Peso Total Galho]]-(Tabela2[[#This Row],[Peso Pç]]*Tabela2[[#This Row],[Qdt Peça Placa]]))*0.9) -> 1.0098 | L20: Sucata | M20: =VLOOKUP(Tabela2[[#This Row],[Tipo de Material]],Dados!$P$2:$Q$4,2,FALSE) -> 15.6 | N20: Jumil | O20: 1
A21: ALÇA TRASEIRA TITAN DIR. ( PROTEC ) | B21: 2 | C21: 0.6 | D21: 2.2 | E21: =((Tabela2[[#This Row],[Peso Total Galho]]-(Tabela2[[#This Row],[Peso Pç]]*Tabela2[[#This Row],[Qdt Peça Placa]]))*0.9) -> 0.9 | L21: Lingote | M21: =VLOOKUP(Tabela2[[#This Row],[Tipo de Material]],Dados!$P$2:$Q$4,2,FALSE) -> 17.6 | N21: Protec
A22: ALÇA TRASEIRA TITAN ESQ. ( PROTEC ) | B22: 2 | C22: 0.6 | D22: 2.2 | E22: =((Tabela2[[#This Row],[Peso Total Galho]]-(Tabela2[[#This Row],[Peso Pç]]*Tabela2[[#This Row],[Qdt Peça Placa]]))*0.9) -> 0.9 | L22: Lingote | M22: =VLOOKUP(Tabela2[[#This Row],[Tipo de Material]],Dados!$P$2:$Q$4,2,FALSE) -> 17.6 | N22: Protec
A23: ANEL 300mm - TRATOMAG | B23: 1 | C23: 19.2 | D23: 20.6 | E23: =((Tabela2[[#This Row],[Peso Total Galho]]-(Tabela2[[#This Row],[Peso Pç]]*Tabela2[[#This Row],[Qdt Peça Placa]]))*0.9) -> 1.26 | L23: Lingote | M23: =VLOOKUP(Tabela2[[#This Row],[Tipo de Material]],Dados!$P$2:$Q$4,2,FALSE) -> 17.6 | N23: TRATOMAG
A24: BASE DE ACENTAMENTO DO DEPOSITO - FUNDIDO | B24: 4 | C24: 0.774 | D24: 5.472 | E24: =((Tabela2[[#This Row],[Peso Total Galho]]-(Tabela2[[#This Row],[Peso Pç]]*Tabela2[[#This Row],[Qdt Peça Placa]]))*0.9) -> 2.1384 | L24: Sucata | M24: =VLOOKUP(Tabela2[[#This Row],[Tipo de Material]],Dados!$P$2:$Q$4,2,FALSE) -> 15.6 | N24: Jumil | O24: 4
A25: Base Depósito Semente 2760317 (2749444P) - FUNDIDO | B25: 6 | C25: 0.78 | D25: 8.28 | E25: =((Tabela2[[#This Row],[Peso Total Galho]]-(Tabela2[[#This Row],[Peso Pç]]*Tabela2[[#This Row],[Qdt Peça Placa]]))*0.9) -> 3.24 | G25: 1 | H25: 4.982 | J25: 400402 | L25: Sucata | M25: =VLOOKUP(Tabela2[[#This Row],[Tipo de Material]],Dados!$P$2:$Q$4,2,FALSE) -> 15.6 | N25: Jumil | O25: 10
A26: Base do Deposito 2761086 Fundido | B26: 4 | C26: 0.795 | D26: 5.628 | E26: =((Tabela2[[#This Row],[Peso Total Galho]]-(Tabela2[[#This Row],[Peso Pç]]*Tabela2[[#This Row],[Qdt Peça Placa]]))*0.9) -> 2.2032 | G26: 4 | H26: 1.115 | J26: 400403 | L26: Sucata | M26: =VLOOKUP(Tabela2[[#This Row],[Tipo de Material]],Dados!$P$2:$Q$4,2,FALSE) -> 15.6 | N26: Jumil | O26: 5
A27: BIELA M42 | B27: 10 | C27: 0.16 | D27: 2.5 | E27: =((Tabela2[[#This Row],[Peso Total Galho]]-(Tabela2[[#This Row],[Peso Pç]]*Tabela2[[#This Row],[Qdt Peça Placa]]))*0.9) -> 0.81 | L27: Lingote | M27: =VLOOKUP(Tabela2[[#This Row],[Tipo de Material]],Dados!$P$2:$Q$4,2,FALSE) -> 17.6 | N27: MGA
A28: BLOCO FUNDIDO - MGA | B28: 3 | C28: 2.5 | D28: 8.4 | E28: =((Tabela2[[#This Row],[Peso Total Galho]]-(Tabela2[[#This Row],[Peso Pç]]*Tabela2[[#This Row],[Qdt Peça Placa]]))*0.9) -> 0.81 | L28: Lingote | M28: =VLOOKUP(Tabela2[[#This Row],[Tipo de Material]],Dados!$P$2:$Q$4,2,FALSE) -> 17.6 | N28: MGA
A29: Bocal de Saida 0429034 Fundido | B29: 1 | C29: 1.95 | D29: 2.4 | E29: =((Tabela2[[#This Row],[Peso Total Galho]]-(Tabela2[[#This Row],[Peso Pç]]*Tabela2[[#This Row],[Qdt Peça Placa]]))*0.9) -> 0.405 | G29: 1 | L29: Sucata | M29: =VLOOKUP(Tabela2[[#This Row],[Tipo de Material]],Dados!$P$2:$Q$4,2,FALSE) -> 15.6 | N29: Jumil | O29: 1
A30: Bocal de Saida 2761392 / 0429008 Fundido | B30: 1 | C30: 1.95 | D30: 3.45 | E30: =((Tabela2[[#This Row],[Peso Total Galho]]-(Tabela2[[#This Row],[Peso Pç]]*Tabela2[[#This Row],[Qdt Peça Placa]]))*0.9) -> 1.35 | L30: Sucata | M30: =VLOOKUP(Tabela2[[#This Row],[Tipo de Material]],Dados!$P$2:$Q$4,2,FALSE) -> 15.6 | N30: Jumil | O30: 1
A31: BRACINHO ARTICULADOR | B31: 4 | C31: 0.5 | D31: 3.2 | E31: =((Tabela2[[#This Row],[Peso Total Galho]]-(Tabela2[[#This Row],[Peso Pç]]*Tabela2[[#This Row],[Qdt Peça Placa]]))*0.9) -> 1.08 | L31: Lingote | M31: =VLOOKUP(Tabela2[[#This Row],[Tipo de Material]],Dados!$P$2:$Q$4,2,FALSE) -> 17.6 | N31: Marcelo
A32: CABEÇOTE DUPLO - DANILO | B32: 1 | C32: 20 | D32: 22.3 | E32: =((Tabela2[[#This Row],[Peso Total Galho]]-(Tabela2[[#This Row],[Peso Pç]]*Tabela2[[#This Row],[Qdt Peça Placa]]))*0.9) -> 2.07 | L32: Mistura | M32: =VLOOKUP(Tabela2[[#This Row],[Tipo de Material]],Dados!$P$2:$Q$4,2,FALSE) -> 16.569852 | N32: Danilo
A33: Cachimbo Fundido 33 (-) Fundido | B33: 12 | C33: 0.262 | D33: 5.57 | E33: =((Tabela2[[#This Row],[Peso Total Galho]]-(Tabela2[[#This Row],[Peso Pç]]*Tabela2[[#This Row],[Qdt Peça Placa]]))*0.9) -> 2.1834 | L33: Lingote | M33: =VLOOKUP(Tabela2[[#This Row],[Tipo de Material]],Dados!$P$2:$Q$4,2,FALSE) -> 17.6 | N33: Marcelo | O33: 5
A34: Cachimbo Fundido 34,5 (+) Fundido | B34: 12 | C34: 0.262 | D34: 5.568 | E34: =((Tabela2[[#This Row],[Peso Total Galho]]-(Tabela2[[#This Row],[Peso Pç]]*Tabela2[[#This Row],[Qdt Peça Placa]]))*0.9) -> 2.1816 | L34: Lingote | M34: =VLOOKUP(Tabela2[[#This Row],[Tipo de Material]],Dados!$P$2:$Q$4,2,FALSE) -> 17.6 | N34: Marcelo | O34: 1
A35: CAIXA DA TAMPA 40 Kg - DANILO | B35: 1 | C35: 40 | D35: 40.3 | E35: =((Tabela2[[#This Row],[Peso Total Galho]]-(Tabela2[[#This Row],[Peso Pç]]*Tabela2[[#This Row],[Qdt Peça Placa]]))*0.9) -> 0.27 | L35: Mistura | M35: =VLOOKUP(Tabela2[[#This Row],[Tipo de Material]],Dados!$P$2:$Q$4,2,FALSE) -> 16.569852 | N35: Danilo
A36: CAIXA TUDO DESCO EXATA | B36: 2 | C36: 1.9 | D36: 4.7 | E36: =((Tabela2[[#This Row],[Peso Total Galho]]-(Tabela2[[#This Row],[Peso Pç]]*Tabela2[[#This Row],[Qdt Peça Placa]]))*0.9) -> 0.81 | L36: Lingote | M36: =VLOOKUP(Tabela2[[#This Row],[Tipo de Material]],Dados!$P$2:$Q$4,2,FALSE) -> 17.6 | N36: Marcelo
A37: Caracol HX55 - Fundido | B37: 1 | C37: 3.1 | D37: 3.8 | E37: =((Tabela2[[#This Row],[Peso Total Galho]]-(Tabela2[[#This Row],[Peso Pç]]*Tabela2[[#This Row],[Qdt Peça Placa]]))*0.9) -> 0.63 | G37: 2 | H37: 1.25 | J37: 400301 | L37: Lingote | M37: =VLOOKUP(Tabela2[[#This Row],[Tipo de Material]],Dados!$P$2:$Q$4,2,FALSE) -> 17.6 | N37: Oscar | O37: 20
A38: Caracol S300 John Deere 3520 - Fundido | B38: 1 | C38: 2 | D38: 2.4 | E38: =((Tabela2[[#This Row],[Peso Total Galho]]-(Tabela2[[#This Row],[Peso Pç]]*Tabela2[[#This Row],[Qdt Peça Placa]]))*0.9) -> 0.36 | G38: 2 | H38: 1.175 | J38: 400302 | L38: Lingote | M38: =VLOOKUP(Tabela2[[#This Row],[Tipo de Material]],Dados!$P$2:$Q$4,2,FALSE) -> 17.6 | N38: Oscar | O38: 20
A39: CARCAÇA T-924 | B39: 4 | C39: 0.425 | D39: 2.4 | E39: =((Tabela2[[#This Row],[Peso Total Galho]]-(Tabela2[[#This Row],[Peso Pç]]*Tabela2[[#This Row],[Qdt Peça Placa]]))*0.9) -> 0.63 | L39: Lingote | M39: =VLOOKUP(Tabela2[[#This Row],[Tipo de Material]],Dados!$P$2:$Q$4,2,FALSE) -> 17.6 | N39: TPA/TEMPLA
A40: CARCAÇA T-925 | B40: 4 | C40: 0.575 | D40: 3.4 | E40: =((Tabela2[[#This Row],[Peso Total Galho]]-(Tabela2[[#This Row],[Peso Pç]]*Tabela2[[#This Row],[Qdt Peça Placa]]))*0.9) -> 0.99 | L40: Lingote | M40: =VLOOKUP(Tabela2[[#This Row],[Tipo de Material]],Dados!$P$2:$Q$4,2,FALSE) -> 17.6 | N40: TPA/TEMPLA
...

Sheet Produção
A1: Data | B1: Produto | C1: O.P. | D1: Moldador | E1: Ajudante | F1: Qtde Cx Produzida | G1: Tempo | H1: Perda Pçs | I1: Custo / Kg Util | J1: Custo / Pç | K1: Cx/H | L1: Previsto | M1: Realizado | N1: % Perda | O1: Tempo / Cx | P1: Cx Perdida | Q1: Aluminio Util | R1: Aluminio Bruto | S1: Retorno Aluminio | T1: Qtde Oleo | U1: Custo M.O. / H | V1: Custo / Cx Moldada | W1: Custo M.O. Total | X1: Custo Aluminio | Y1: Custo Machos | Z1: Custo Oleo | AA1: Custo Total | AB1: Custo da Perda | AC1: Qdt Peça Placa | AD1: Peso Util/Pç | AE1: Peso Total Galho | AF1: Canal Retorno | AG1: Peso Caixa Areia | AH1: Qde macho / CX | AI1: Peso Macho | AJ1: Custo/Kg | AK1: Cliente | AL1: Custo Usinagem | AM1: Valor Mínimo Venda | AN1: Tabela 1 | AO1: Tabela 2 | AP1: Tabela 3
A2: 45691 | B2: PROTEC TITAN 150 DIR | C2: 5169 | D2: Daniel Garcia | E2: Victor Hugo | F2: 30 | G2: 0.12291667 | H2: 1 | I2: =IFERROR(Tabela3[[#This Row],[Custo Total]]/Tabela3[[#This Row],[Aluminio Util]],0) -> 27.591322 | J2: =Tabela3[[#This Row],[Custo Total]]/Tabela3[[#This Row],[Realizado]] -> 35.868719 | K2: =IFERROR(Tabela3[[#This Row],[Qtde Cx Produzida]]/Tabela3[[#This Row],[Tempo]]/24,0) -> 10.169492 | L2: =Tabela3[[#This Row],[Qtde Cx Produzida]]*Tabela3[[#This Row],[Qdt Peça Placa]] -> 30 | M2: =Tabela3[[#This Row],[Previsto]]-Tabela3[[#This Row],[Perda Pçs]] -> 29 | N2: =IFERROR(Tabela3[[#This Row],[Perda Pçs]]/Tabela3[[#This Row],[Previsto]],0) -> 0.033333333 | O2: =IFERROR(IF(Tabela3[[#This Row],[Qtde Cx Produzida]] <> 0, Tabela3[[#This Row],[Tempo]] / Tabela3[[#This Row],[Qtde Cx Produzida]], 0),0) -> 0.0040972222 | P2: =IFERROR(Tabela3[[#This Row],[Perda Pçs]]/Tabela3[[#This Row],[Qdt Peça Placa]],0) -> 1 | Q2: =IFERROR(Tabela3[[#This Row],[Realizado]]*Tabela3[[#This Row],[Peso Util/Pç]],0) -> 37.7 | R2: =IFERROR(Tabela3[[#This Row],[Peso Total Galho]]*Tabela3[[#This Row],[Qtde Cx Produzida]]*1.055,0) -> 64.8825 | S2: =(Tabela3[[#This Row],[Aluminio Bruto]]-Tabela3[[#This Row],[Aluminio Util]])*0.9 -> 24.46425 | T2: =Tabela3[[#This Row],[Aluminio Bruto]]/OleoKGAluminio -> 27.295984 | U2: =IFERROR((VLOOKUP(Tabela3[[#This Row],[Moldador]],Tabela1[],5,)+(VLOOKUP(Tabela3[[#This Row],[Ajudante]],Tabela1[],5,))*3.5),0) -> 99.950346 | V2: =IFERROR(Tabela3[[#This Row],[Custo M.O. / H]]/((Tabela3[[#This Row],[Realizado]]/Tabela3[[#This Row],[Qdt Peça Placa]])/Tabela3[[#This Row],[Tempo]]/24),) -> 10.167363 | W2: =Tabela3[[#This Row],[Custo / Cx Moldada]]*Tabela3[[#This Row],[Qtde Cx Produzida]] -> 305.02088 | X2: =Tabela3[[#This Row],[Aluminio Util]]*Tabela3[[#This Row],[Custo/Kg]] -> 663.52 | Y2: =IFERROR(VLOOKUP(Tabela3[[#This Row],[Data]],Tabela461213[],2,1)*(Tabela3[[#This Row],[Qtde Cx Produzida]]*Tabela3[[#This Row],[Qde macho / CX]]*Tabela3[[#This Row],[Peso Macho]]),) -> 0 | Z2: =IFERROR(Tabela3[[#This Row],[Qtde Oleo]]*(VLOOKUP(Tabela3[[#This Row],[Data]],CompraOleo[],3,TRUE))*1.05,0) -> 71.651958 | AA2: =(Tabela3[[#This Row],[Custo Oleo]]+Tabela3[[#This Row],[Custo Aluminio]]+Tabela3[[#This Row],[Custo M.O. Total]]+Tabela3[[#This Row],[Custo Machos]]) -> 1040.1928 | AB2: =Tabela3[[#This Row],[Custo Total]]*Tabela3[[#This Row],[% Perda]] -> 34.673095 | AC2: =IFERROR(VLOOKUP(Tabela3[[#This Row],[Produto]],Tabela2[],2,0),0) -> 1 | AD2: =IFERROR(VLOOKUP(Tabela3[[#This Row],[Produto]],Tabela2[],3,0),0) -> 1.3 | AE2: =IFERROR(VLOOKUP(Tabela3[[#This Row],[Produto]],Tabela2[],4,0),0) -> 2.05 | AF2: =IFERROR(VLOOKUP(Tabela3[[#This Row],[Produto]],Tabela2[],5,0),0) -> 0.675 | AG2: =IFERROR(VLOOKUP(Tabela3[[#This Row],[Produto]],Tabela2[],6,0),0) -> 0 | AH2: =IFERROR(VLOOKUP(Tabela3[[#This Row],[Produto]],Tabela2[],7,0),0) -> 0 | AI2: =IFERROR(VLOOKUP(Tabela3[[#This Row],[Produto]],Tabela2[],8,0),0) -> 0 | AJ2: =IFERROR(VLOOKUP(Tabela3[[#This Row],[Produto]],Tabela2[],13,0),0) -> 17.6 | AK2: =IFERROR(VLOOKUP(Tabela3[[#This Row],[Produto]],Tabela2[],14,0),0) -> Protec | AL2: =IFERROR(VLOOKUP(Tabela3[[#This Row],[Produto]],Tabela2[],15,0),0) -> 0 | AM2: =(Tabela3[[#This Row],[Custo Usinagem]]+Tabela3[[#This Row],[Custo / Pç]])*1.2 -> 43.042462 | AN2: =Tabela3[[#This Row],[Valor Mínimo Venda]]*1.15 -> 49.498832 | AO2: =Tabela3[[#This Row],[Tabela 1]]*1.08 -> 53.458738 | AP2: =Tabela3[[#This Row],[Tabela 2]]*1.15 -> 61.477549
A3: 45691 | B3: PROTEC TITAN 150 DIR | C3: 5169 | D3: Marcelo Santos | E3: Claudio Henrique | F3: 30 | G3: 0.125 | H3: 2 | I3: =IFERROR(Tabela3[[#This Row],[Custo Total]]/Tabela3[[#This Row],[Aluminio Util]],0) -> 28.394531 | J3: =Tabela3[[#This Row],[Custo Total]]/Tabela3[[#This Row],[Realizado]] -> 36.91289 | K3: =IFERROR(Tabela3[[#This Row],[Qtde Cx Produzida]]/Tabela3[[#This Row],[Tempo]]/24,0) -> 10 | L3: =Tabela3[[#This Row],[Qtde Cx Produzida]]*Tabela3[[#This Row],[Qdt Peça Placa]] -> 30 | M3: =Tabela3[[#This Row],[Previsto]]-Tabela3[[#This Row],[Perda Pçs]] -> 28 | N3: =IFERROR(Tabela3[[#This Row],[Perda Pçs]]/Tabela3[[#This Row],[Previsto]],0) -> 0.066666667 | O3: =IFERROR(IF(Tabela3[[#This Row],[Qtde Cx Produzida]] <> 0, Tabela3[[#This Row],[Tempo]] / Tabela3[[#This Row],[Qtde Cx Produzida]], 0),0) -> 0.0041666667 | P3: =IFERROR(Tabela3[[#This Row],[Perda Pçs]]/Tabela3[[#This Row],[Qdt Peça Placa]],0) -> 2 | Q3: =IFERROR(Tabela3[[#This Row],[Realizado]]*Tabela3[[#This Row],[Peso Util/Pç]],0) -> 36.4 | R3: =IFERROR(Tabela3[[#This Row],[Peso Total Galho]]*Tabela3[[#This Row],[Qtde Cx Produzida]]*1.055,0) -> 64.8825 | S3: =(Tabela3[[#This Row],[Aluminio Bruto]]-Tabela3[[#This Row],[Aluminio Util]])*0.9 -> 25.63425 | T3: =Tabela3[[#This Row],[Aluminio Bruto]]/OleoKGAluminio -> 27.295984 | U3: =IFERROR((VLOOKUP(Tabela3[[#This Row],[Moldador]],Tabela1[],5,)+(VLOOKUP(Tabela3[[#This Row],[Ajudante]],Tabela1[],5,))*3.5),0) -> 99.950346 | V3: =IFERROR(Tabela3[[#This Row],[Custo M.O. / H]]/((Tabela3[[#This Row],[Realizado]]/Tabela3[[#This Row],[Qdt Peça Placa]])/Tabela3[[#This Row],[Tempo]]/24),) -> 10.708966 | W3: =Tabela3[[#This Row],[Custo / Cx Moldada]]*Tabela3[[#This Row],[Qtde Cx Produzida]] -> 321.26897 | X3: =Tabela3[[#This Row],[Aluminio Util]]*Tabela3[[#This Row],[Custo/Kg]] -> 640.64 | Y3: =IFERROR(VLOOKUP(Tabela3[[#This Row],[Data]],Tabela461213[],2,1)*(Tabela3[[#This Row],[Qtde Cx Produzida]]*Tabela3[[#This Row],[Qde macho / CX]]*Tabela3[[#This Row],[Peso Macho]]),) -> 0 | Z3: =IFERROR(Tabela3[[#This Row],[Qtde Oleo]]*(VLOOKUP(Tabela3[[#This Row],[Data]],CompraOleo[],3,TRUE))*1.05,0) -> 71.651958 | AA3: =(Tabela3[[#This Row],[Custo Oleo]]+Tabela3[[#This Row],[Custo Aluminio]]+Tabela3[[#This Row],[Custo M.O. Total]]+Tabela3[[#This Row],[Custo Machos]]) -> 1033.5609 | AB3: =Tabela3[[#This Row],[Custo Total]]*Tabela3[[#This Row],[% Perda]] -> 68.904062 | AC3: =IFERROR(VLOOKUP(Tabela3[[#This Row],[Produto]],Tabela2[],2,0),0) -> 1 | AD3: =IFERROR(VLOOKUP(Tabela3[[#This Row],[Produto]],Tabela2[],3,0),0) -> 1.3 | AE3: =IFERROR(VLOOKUP(Tabela3[[#This Row],[Produto]],Tabela2[],4,0),0) -> 2.05 | AF3: =IFERROR(VLOOKUP(Tabela3[[#This Row],[Produto]],Tabela2[],5,0),0) -> 0.675 | AG3: =IFERROR(VLOOKUP(Tabela3[[#This Row],[Produto]],Tabela2[],6,0),0) -> 0 | AH3: =IFERROR(VLOOKUP(Tabela3[[#This Row],[Produto]],Tabela2[],7,0),0) -> 0 | AI3: =IFERROR(VLOOKUP(Tabela3[[#This Row],[Produto]],Tabela2[],8,0),0) -> 0 | AJ3: =IFERROR(VLOOKUP(Tabela3[[#This Row],[Produto]],Tabela2[],13,0),0) -> 17.6 | AK3: =IFERROR(VLOOKUP(Tabela3[[#This Row],[Produto]],Tabela2[],14,0),0) -> Protec | AL3: =IFERROR(VLOOKUP(Tabela3[[#This Row],[Produto]],Tabela2[],15,0),0) -> 0 | AM3: =(Tabela3[[#This Row],[Custo Usinagem]]+Tabela3[[#This Row],[Custo / Pç]])*1.2 -> 44.295468 | AN3: =Tabela3[[#This Row],[Valor Mínimo Venda]]*1.15 -> 50.939789 | AO3: =Tabela3[[#This Row],[Tabela 1]]*1.08 -> 55.014972 | AP3: =Tabela3[[#This Row],[Tabela 2]]*1.15 -> 63.267217
A4: 45691 | B4: Prot Câm Dome C Acopl - SENUN METAL | C4: 5309 | D4: Daniel Garcia | E4: Victor Hugo | F4: 40 | G4: 0.17847222 | H4: 10 | I4: =IFERROR(Tabela3[[#This Row],[Custo Total]]/Tabela3[[#This Row],[Aluminio Util]],0) -> 23.475382 | J4: =Tabela3[[#This Row],[Custo Total]]/Tabela3[[#This Row],[Realizado]] -> 7.0895653 | K4: =IFERROR(Tabela3[[#This Row],[Qtde Cx Produzida]]/Tabela3[[#This Row],[Tempo]]/24,0) -> 9.3385214 | L4: =Tabela3[[#This Row],[Qtde Cx Produzida]]*Tabela3[[#This Row],[Qdt Peça Placa]] -> 240 | M4: =Tabela3[[#This Row],[Previsto]]-Tabela3[[#This Row],[Perda Pçs]] -> 230 | N4: =IFERROR(Tabela3[[#This Row],[Perda Pçs]]/Tabela3[[#This Row],[Previsto]],0) -> 0.041666667 | O4: =IFERROR(IF(Tabela3[[#This Row],[Qtde Cx Produzida]] <> 0, Tabela3[[#This Row],[Tempo]] / Tabela3[[#This Row],[Qtde Cx Produzida]], 0),0) -> 0.0044618056 | P4: =IFERROR(Tabela3[[#This Row],[Perda Pçs]]/Tabela3[[#This Row],[Qdt Peça Placa]],0) -> 1.6666667 | Q4: =IFERROR(Tabela3[[#This Row],[Realizado]]*Tabela3[[#This Row],[Peso Util/Pç]],0) -> 69.46 | R4: =IFERROR(Tabela3[[#This Row],[Peso Total Galho]]*Tabela3[[#This Row],[Qtde Cx Produzida]]*1.055,0) -> 90.8144 | S4: =(Tabela3[[#This Row],[Aluminio Bruto]]-Tabela3[[#This Row],[Aluminio Util]])*0.9 -> 19.21896 | T4: =Tabela3[[#This Row],[Aluminio Bruto]]/OleoKGAluminio -> 38.205501 | U4: =IFERROR((VLOOKUP(Tabela3[[#This Row],[Moldador]],Tabela1[],5,)+(VLOOKUP(Tabela3[[#This Row],[Ajudante]],Tabela1[],5,))*3.5),0) -> 99.950346 | V4: =IFERROR(Tabela3[[#This Row],[Custo M.O. / H]]/((Tabela3[[#This Row],[Realizado]]/Tabela3[[#This Row],[Qdt Peça Placa]])/Tabela3[[#This Row],[Tempo]]/24),) -> 11.168365 | W4: =Tabela3[[#This Row],[Custo / Cx Moldada]]*Tabela3[[#This Row],[Qtde Cx Produzida]] -> 446.73459 | X4: =Tabela3[[#This Row],[Aluminio Util]]*Tabela3[[#This Row],[Custo/Kg]] -> 1083.576 | Y4: =IFERROR(VLOOKUP(Tabela3[[#This Row],[Data]],Tabela461213[],2,1)*(Tabela3[[#This Row],[Qtde Cx Produzida]]*Tabela3[[#This Row],[Qde macho / CX]]*Tabela3[[#This Row],[Peso Macho]]),) -> 0 | Z4: =IFERROR(Tabela3[[#This Row],[Qtde Oleo]]*(VLOOKUP(Tabela3[[#This Row],[Data]],CompraOleo[],3,TRUE))*1.05,0) -> 100.28944 | AA4: =(Tabela3[[#This Row],[Custo Oleo]]+Tabela3[[#This Row],[Custo Aluminio]]+Tabela3[[#This Row],[Custo M.O. Total]]+Tabela3[[#This Row],[Custo Machos]]) -> 1630.6 | AB4: =Tabela3[[#This Row],[Custo Total]]*Tabela3[[#This Row],[% Perda]] -> 67.941668 | AC4: =IFERROR(VLOOKUP(Tabela3[[#This Row],[Produto]],Tabela2[],2,0),0) -> 6 | AD4: =IFERROR(VLOOKUP(Tabela3[[#This Row],[Produto]],Tabela2[],3,0),0) -> 0.302 | AE4: =IFERROR(VLOOKUP(Tabela3[[#This Row],[Produto]],Tabela2[],4,0),0) -> 2.152 | AF4: =IFERROR(VLOOKUP(Tabela3[[#This Row],[Produto]],Tabela2[],5,0),0) -> 0.306 | AG4: =IFERROR(VLOOKUP(Tabela3[[#This Row],[Produto]],Tabela2[],6,0),0) -> 0 | AH4: =IFERROR(VLOOKUP(Tabela3[[#This Row],[Produto]],Tabela2[],7,0),0) -> 0 | AI4: =IFERROR(VLOOKUP(Tabela3[[#This Row],[Produto]],Tabela2[],8,0),0) -> 0 | AJ4: =IFERROR(VLOOKUP(Tabela3[[#This Row],[Produto]],Tabela2[],13,0),0) -> 15.6 | AK4: =IFERROR(VLOOKUP(Tabela3[[#This Row],[Produto]],Tabela2[],14,0),0) -> Senun | AL4: =IFERROR(VLOOKUP(Tabela3[[#This Row],[Produto]],Tabela2[],15,0),0) -> 4 | AM4: =(Tabela3[[#This Row],[Custo Usinagem]]+Tabela3[[#This Row],[Custo / Pç]])*1.2 -> 13.307478 | AN4: =Tabela3[[#This Row],[Valor Mínimo Venda]]*1.15 -> 15.3036 | AO4: =Tabela3[[#This Row],[Tabela 1]]*1.08 -> 16.527888 | AP4: =Tabela3[[#This Row],[Tabela 2]]*1.15 -> 19.007071
A5: 45691 | B5: Distribuidor de Ar 8s 2761098 (3241145P) - FUNDIDO | C5: 5223 | D5: Marcelo Santos | E5: Claudio Henrique | F5: 20 | G5: 0.098611111 | H5: 1 | I5: =IFERROR(Tabela3[[#This Row],[Custo Total]]/Tabela3[[#This Row],[Aluminio Util]],0) -> 27.542987 | J5: =Tabela3[[#This Row],[Custo Total]]/Tabela3[[#This Row],[Realizado]] -> 48.751087 | K5: =IFERROR(Tabela3[[#This Row],[Qtde Cx Produzida]]/Tabela3[[#This Row],[Tempo]]/24,0) -> 8.4507042 | L5: =Tabela3[[#This Row],[Qtde Cx Produzida]]*Tabela3[[#This Row],[Qdt Peça Placa]] -> 20 | M5: =Tabela3[[#This Row],[Previsto]]-Tabela3[[#This Row],[Perda Pçs]] -> 19 | N5: =IFERROR(Tabela3[[#This Row],[Perda Pçs]]/Tabela3[[#This Row],[Previsto]],0) -> 0.05 | O5: =IFERROR(IF(Tabela3[[#This Row],[Qtde Cx Produzida]] <> 0, Tabela3[[#This Row],[Tempo]] / Tabela3[[#This Row],[Qtde Cx Produzida]], 0),0) -> 0.0049305556 | P5: =IFERROR(Tabela3[[#This Row],[Perda Pçs]]/Tabela3[[#This Row],[Qdt Peça Placa]],0) -> 1 | Q5: =IFERROR(Tabela3[[#This Row],[Realizado]]*Tabela3[[#This Row],[Peso Util/Pç]],0) -> 33.63 | R5: =IFERROR(Tabela3[[#This Row],[Peso Total Galho]]*Tabela3[[#This Row],[Qtde Cx Produzida]]*1.055,0) -> 66.043 | S5: =(Tabela3[[#This Row],[Aluminio Bruto]]-Tabela3[[#This Row],[Aluminio Util]])*0.9 -> 29.1717 | T5: =Tabela3[[#This Row],[Aluminio Bruto]]/OleoKGAluminio -> 27.784205 | U5: =IFERROR((VLOOKUP(Tabela3[[#This Row],[Moldador]],Tabela1[],5,)+(VLOOKUP(Tabela3[[#This Row],[Ajudante]],Tabela1[],5,))*3.5),0) -> 99.950346 | V5: =IFERROR(Tabela3[[#This Row],[Custo M.O. / H]]/((Tabela3[[#This Row],[Realizado]]/Tabela3[[#This Row],[Qdt Peça Placa]])/Tabela3[[#This Row],[Tempo]]/24),) -> 12.449955 | W5: =Tabela3[[#This Row],[Custo / Cx Moldada]]*Tabela3[[#This Row],[Qtde Cx Produzida]] -> 248.99911 | X5: =Tabela3[[#This Row],[Aluminio Util]]*Tabela3[[#This Row],[Custo/Kg]] -> 524.628 | Y5: =IFERROR(VLOOKUP(Tabela3[[#This Row],[Data]],Tabela461213[],2,1)*(Tabela3[[#This Row],[Qtde Cx Produzida]]*Tabela3[[#This Row],[Qde macho / CX]]*Tabela3[[#This Row],[Peso Macho]]),) -> 79.71 | Z5: =IFERROR(Tabela3[[#This Row],[Qtde Oleo]]*(VLOOKUP(Tabela3[[#This Row],[Data]],CompraOleo[],3,TRUE))*1.05,0) -> 72.933537 | AA5: =(Tabela3[[#This Row],[Custo Oleo]]+Tabela3[[#This Row],[Custo Aluminio]]+Tabela3[[#This Row],[Custo M.O. Total]]+Tabela3[[#This Row],[Custo Machos]]) -> 926.27064 | AB5: =Tabela3[[#This Row],[Custo Total]]*Tabela3[[#This Row],[% Perda]] -> 46.313532 | AC5: =IFERROR(VLOOKUP(Tabela3[[#This Row],[Produto]],Tabela2[],2,0),0) -> 1 | AD5: =IFERROR(VLOOKUP(Tabela3[[#This Row],[Produto]],Tabela2[],3,0),0) -> 1.77 | AE5: =IFERROR(VLOOKUP(Tabela3[[#This Row],[Produto]],Tabela2[],4,0),0) -> 3.13 | AF5: =IFERROR(VLOOKUP(Tabela3[[#This Row],[Produto]],Tabela2[],5,0),0) -> 1.224 | AG5: =IFERROR(VLOOKUP(Tabela3[[#This Row],[Produto]],Tabela2[],6,0),0) -> 0 | AH5: =IFERROR(VLOOKUP(Tabela3[[#This Row],[Produto]],Tabela2[],7,0),0) -> 1 | AI5: =IFERROR(VLOOKUP(Tabela3[[#This Row],[Produto]],Tabela2[],8,0),0) -> 2.657 | AJ5: =IFERROR(VLOOKUP(Tabela3[[#This Row],[Produto]],Tabela2[],13,0),0) -> 15.6 | AK5: =IFERROR(VLOOKUP(Tabela3[[#This Row],[Produto]],Tabela2[],14,0),0) -> Jumil | AL5: =IFERROR(VLOOKUP(Tabela3[[#This Row],[Produto]],Tabela2[],15,0),0) -> 10 | AM5: =(Tabela3[[#This Row],[Custo Usinagem]]+Tabela3[[#This Row],[Custo / Pç]])*1.2 -> 70.501304 | AN5: =Tabela3[[#This Row],[Valor Mínimo Venda]]*1.15 -> 81.076499 | AO5: =Tabela3[[#This Row],[Tabela 1]]*1.08 -> 87.562619 | AP5: =Tabela3[[#This Row],[Tabela 2]]*1.15 -> 100.69701
A6: 45692 | B6: Centro da Banda (3224429P) - Fundido | C6: 5295 | D6: Daniel Garcia | E6: Victor Hugo | F6: 10 | G6: 0.034027778 | H6: 0 | I6: =IFERROR(Tabela3[[#This Row],[Custo Total]]/Tabela3[[#This Row],[Aluminio Util]],0) -> 22.49123 | J6: =Tabela3[[#This Row],[Custo Total]]/Tabela3[[#This Row],[Realizado]] -> 38.010178 | K6: =IFERROR(Tabela3[[#This Row],[Qtde Cx Produzida]]/Tabela3[[#This Row],[Tempo]]/24,0) -> 12.244898 | L6: =Tabela3[[#This Row],[Qtde Cx Produzida]]*Tabela3[[#This Row],[Qdt Peça Placa]] -> 10 | M6: =Tabela3[[#This Row],[Previsto]]-Tabela3[[#This Row],[Perda Pçs]] -> 10 | N6: =IFERROR(Tabela3[[#This Row],[Perda Pçs]]/Tabela3[[#This Row],[Previsto]],0) -> 0 | O6: =IFERROR(IF(Tabela3[[#This Row],[Qtde Cx Produzida]] <> 0, Tabela3[[#This Row],[Tempo]] / Tabela3[[#This Row],[Qtde Cx Produzida]], 0),0) -> 0.0034027778 | P6: =IFERROR(Tabela3[[#This Row],[Perda Pçs]]/Tabela3[[#This Row],[Qdt Peça Placa]],0) -> 0 | Q6: =IFERROR(Tabela3[[#This Row],[Realizado]]*Tabela3[[#This Row],[Peso Util/Pç]],0) -> 16.9 | R6: =IFERROR(Tabela3[[#This Row],[Peso Total Galho]]*Tabela3[[#This Row],[Qtde Cx Produzida]]*1.055,0) -> 31.5445 | S6: =(Tabela3[[#This Row],[Aluminio Bruto]]-Tabela3[[#This Row],[Aluminio Util]])*0.9 -> 13.18005 | T6: =Tabela3[[#This Row],[Aluminio Bruto]]/OleoKGAluminio -> 13.27073 | U6: =IFERROR((VLOOKUP(Tabela3[[#This Row],[Moldador]],Tabela1[],5,)+(VLOOKUP(Tabela3[[#This Row],[Ajudante]],Tabela1[],5,))*3.5),0) -> 99.950346 | V6: =IFERROR(Tabela3[[#This Row],[Custo M.O. / H]]/((Tabela3[[#This Row],[Realizado]]/Tabela3[[#This Row],[Qdt Peça Placa]])/Tabela3[[#This Row],[Tempo]]/24),) -> 8.1626116 | W6: =Tabela3[[#This Row],[Custo / Cx Moldada]]*Tabela3[[#This Row],[Qtde Cx Produzida]] -> 81.626116 | X6: =Tabela3[[#This Row],[Aluminio Util]]*Tabela3[[#This Row],[Custo/Kg]] -> 263.64 | Y6: =IFERROR(VLOOKUP(Tabela3[[#This Row],[Data]],Tabela461213[],2,1)*(Tabela3[[#This Row],[Qtde Cx Produzida]]*Tabela3[[#This Row],[Qde macho / CX]]*Tabela3[[#This Row],[Peso Macho]]),) -> 0 | Z6: =IFERROR(Tabela3[[#This Row],[Qtde Oleo]]*(VLOOKUP(Tabela3[[#This Row],[Data]],CompraOleo[],3,TRUE))*1.05,0) -> 34.835667 | AA6: =(Tabela3[[#This Row],[Custo Oleo]]+Tabela3[[#This Row],[Custo Aluminio]]+Tabela3[[#This Row],[Custo M.O. Total]]+Tabela3[[#This Row],[Custo Machos]]) -> 380.10178 | AB6: =Tabela3[[#This Row],[Custo Total]]*Tabela3[[#This Row],[% Perda]] -> 0 | AC6: =IFERROR(VLOOKUP(Tabela3[[#This Row],[Produto]],Tabela2[],2,0),0) -> 1 | AD6: =IFERROR(VLOOKUP(Tabela3[[#This Row],[Produto]],Tabela2[],3,0),0) -> 1.69 | AE6: =IFERROR(VLOOKUP(Tabela3[[#This Row],[Produto]],Tabela2[],4,0),0) -> 2.99 | AF6: =IFERROR(VLOOKUP(Tabela3[[#This Row],[Produto]],Tabela2[],5,0),0) -> 1.17 | AG6: =IFERROR(VLOOKUP(Tabela3[[#This Row],[Produto]],Tabela2[],6,0),0) -> 0 | AH6: =IFERROR(VLOOKUP(Tabela3[[#This Row],[Produto]],Tabela2[],7,0),0) -> 0 | AI6: =IFERROR(VLOOKUP(Tabela3[[#This Row],[Produto]],Tabela2[],8,0),0) -> 0 | AJ6: =IFERROR(VLOOKUP(Tabela3[[#This Row],[Produto]],Tabela2[],13,0),0) -> 15.6 | AK6: =IFERROR(VLOOKUP(Tabela3[[#This Row],[Produto]],Tabela2[],14,0),0) -> Jumil | AL6: =IFERROR(VLOOKUP(Tabela3[[#This Row],[Produto]],Tabela2[],15,0),0) -> 8 | AM6: =(Tabela3[[#This Row],[Custo Usinagem]]+Tabela3[[#This Row],[Custo / Pç]])*1.2 -> 55.212214 | AN6: =Tabela3[[#This Row],[Valor Mínimo Venda]]*1.15 -> 63.494046 | AO6: =Tabela3[[#This Row],[Tabela 1]]*1.08 -> 68.57357 | AP6: =Tabela3[[#This Row],[Tabela 2]]*1.15 -> 78.859605
A7: 45692 | B7: PROTEC TITAN 2000 ES | C7: 5173 | D7: Daniel Garcia | E7: Victor Hugo | F7: 55 | G7: 0.22777778 | H7: 4 | I7: =IFERROR(Tabela3[[#This Row],[Custo Total]]/Tabela3[[#This Row],[Aluminio Util]],0) -> 25.880499 | J7: =Tabela3[[#This Row],[Custo Total]]/Tabela3[[#This Row],[Realizado]] -> 22.541915 | K7: =IFERROR(Tabela3[[#This Row],[Qtde Cx Produzida]]/Tabela3[[#This Row],[Tempo]]/24,0) -> 10.060976 | L7: =Tabela3[[#This Row],[Qtde Cx Produzida]]*Tabela3[[#This Row],[Qdt Peça Placa]] -> 110 | M7: =Tabela3[[#This Row],[Previsto]]-Tabela3[[#This Row],[Perda Pçs]] -> 106 | N7: =IFERROR(Tabela3[[#This Row],[Perda Pçs]]/Tabela3[[#This Row],[Previsto]],0) -> 0.036363636 | O7: =IFERROR(IF(Tabela3[[#This Row],[Qtde Cx Produzida]] <> 0, Tabela3[[#This Row],[Tempo]] / Tabela3[[#This Row],[Qtde Cx Produzida]], 0),0) -> 0.0041414141 | P7: =IFERROR(Tabela3[[#This Row],[Perda Pçs]]/Tabela3[[#This Row],[Qdt Peça Placa]],0) -> 2 | Q7: =IFERROR(Tabela3[[#This Row],[Realizado]]*Tabela3[[#This Row],[Peso Util/Pç]],0) -> 92.326 | R7: =IFERROR(Tabela3[[#This Row],[Peso Total Galho]]*Tabela3[[#This Row],[Qtde Cx Produzida]]*1.055,0) -> 178.83305 | S7: =(Tabela3[[#This Row],[Aluminio Bruto]]-Tabela3[[#This Row],[Aluminio Util]])*0.9 -> 77.856345 | T7: =Tabela3[[#This Row],[Aluminio Bruto]]/OleoKGAluminio -> 75.234833 | U7: =IFERROR((VLOOKUP(Tabela3[[#This Row],[Moldador]],Tabela1[],5,)+(VLOOKUP(Tabela3[[#This Row],[Ajudante]],Tabela1[],5,))*3.5),0) -> 99.950346 | V7: =IFERROR(Tabela3[[#This Row],[Custo M.O. / H]]/((Tabela3[[#This Row],[Realizado]]/Tabela3[[#This Row],[Qdt Peça Placa]])/Tabela3[[#This Row],[Tempo]]/24),) -> 10.309344 | W7: =Tabela3[[#This Row],[Custo / Cx Moldada]]*Tabela3[[#This Row],[Qtde Cx Produzida]] -> 567.01391 | X7: =Tabela3[[#This Row],[Aluminio Util]]*Tabela3[[#This Row],[Custo/Kg]] -> 1624.9376 | Y7: =IFERROR(VLOOKUP(Tabela3[[#This Row],[Data]],Tabela461213[],2,1)*(Tabela3[[#This Row],[Qtde Cx Produzida]]*Tabela3[[#This Row],[Qde macho / CX]]*Tabela3[[#This Row],[Peso Macho]]),) -> 0 | Z7: =IFERROR(Tabela3[[#This Row],[Qtde Oleo]]*(VLOOKUP(Tabela3[[#This Row],[Data]],CompraOleo[],3,TRUE))*1.05,0) -> 197.49144 | AA7: =(Tabela3[[#This Row],[Custo Oleo]]+Tabela3[[#This Row],[Custo Aluminio]]+Tabela3[[#This Row],[Custo M.O. Total]]+Tabela3[[#This Row],[Custo Machos]]) -> 2389.4429 | AB7: =Tabela3[[#This Row],[Custo Total]]*Tabela3[[#This Row],[% Perda]] -> 86.888834 | AC7: =IFERROR(VLOOKUP(Tabela3[[#This Row],[Produto]],Tabela2[],2,0),0) -> 2 | AD7: =IFERROR(VLOOKUP(Tabela3[[#This Row],[Produto]],Tabela2[],3,0),0) -> 0.871 | AE7: =IFERROR(VLOOKUP(Tabela3[[#This Row],[Produto]],Tabela2[],4,0),0) -> 3.082 | AF7: =IFERROR(VLOOKUP(Tabela3[[#This Row],[Produto]],Tabela2[],5,0),0) -> 1.206 | AG7: =IFERROR(VLOOKUP(Tabela3[[#This Row],[Produto]],Tabela2[],6,0),0) -> 0 | AH7: =IFERROR(VLOOKUP(Tabela3[[#This Row],[Produto]],Tabela2[],7,0),0) -> 0 | AI7: =IFERROR(VLOOKUP(Tabela3[[#This Row],[Produto]],Tabela2[],8,0),0) -> 0 | AJ7: =IFERROR(VLOOKUP(Tabela3[[#This Row],[Produto]],Tabela2[],13,0),0) -> 17.6 | AK7: =IFERROR(VLOOKUP(Tabela3[[#This Row],[Produto]],Tabela2[],14,0),0) -> Protec | AL7: =IFERROR(VLOOKUP(Tabela3[[#This Row],[Produto]],Tabela2[],15,0),0) -> 0 | AM7: =(Tabela3[[#This Row],[Custo Usinagem]]+Tabela3[[#This Row],[Custo / Pç]])*1.2 -> 27.050298 | AN7: =Tabela3[[#This Row],[Valor Mínimo Venda]]*1.15 -> 31.107842 | AO7: =Tabela3[[#This Row],[Tabela 1]]*1.08 -> 33.59647 | AP7: =Tabela3[[#This Row],[Tabela 2]]*1.15 -> 38.63594
A8: 45692 | B8: Prot Câm Dome C Acopl - SENUN METAL | C8: 5309 | D8: Daniel Garcia | E8: Victor Hugo | F8: 25 | G8: 0.082638889 | H8: 0 | I8: =IFERROR(Tabela3[[#This Row],[Custo Total]]/Tabela3[[#This Row],[Aluminio Util]],0) -> 21.35973 | J8: =Tabela3[[#This Row],[Custo Total]]/Tabela3[[#This Row],[Realizado]] -> 6.4506383 | K8: =IFERROR(Tabela3[[#This Row],[Qtde Cx Produzida]]/Tabela3[[#This Row],[Tempo]]/24,0) -> 12.605042 | L8: =Tabela3[[#This Row],[Qtde Cx Produzida]]*Tabela3[[#This Row],[Qdt Peça Placa]] -> 150 | M8: =Tabela3[[#This Row],[Previsto]]-Tabela3[[#This Row],[Perda Pçs]] -> 150 | N8: =IFERROR(Tabela3[[#This Row],[Perda Pçs]]/Tabela3[[#This Row],[Previsto]],0) -> 0 | O8: =IFERROR(IF(Tabela3[[#This Row],[Qtde Cx Produzida]] <> 0, Tabela3[[#This Row],[Tempo]] / Tabela3[[#This Row],[Qtde Cx Produzida]], 0),0) -> 0.0033055556 | P8: =IFERROR(Tabela3[[#This Row],[Perda Pçs]]/Tabela3[[#This Row],[Qdt Peça Placa]],0) -> 0 | Q8: =IFERROR(Tabela3[[#This Row],[Realizado]]*Tabela3[[#This Row],[Peso Util/Pç]],0) -> 45.3 | R8: =IFERROR(Tabela3[[#This Row],[Peso Total Galho]]*Tabela3[[#This Row],[Qtde Cx Produzida]]*1.055,0) -> 56.759 | S8: =(Tabela3[[#This Row],[Aluminio Bruto]]-Tabela3[[#This Row],[Aluminio Util]])*0.9 -> 10.3131 | T8: =Tabela3[[#This Row],[Aluminio Bruto]]/OleoKGAluminio -> 23.878438 | U8: =IFERROR((VLOOKUP(Tabela3[[#This Row],[Moldador]],Tabela1[],5,)+(VLOOKUP(Tabela3[[#This Row],[Ajudante]],Tabela1[],5,))*3.5),0) -> 99.950346 | V8: =IFERROR(Tabela3[[#This Row],[Custo M.O. / H]]/((Tabela3[[#This Row],[Realizado]]/Tabela3[[#This Row],[Qdt Peça Placa]])/Tabela3[[#This Row],[Tempo]]/24),) -> 7.9293941 | W8: =Tabela3[[#This Row],[Custo / Cx Moldada]]*Tabela3[[#This Row],[Qtde Cx Produzida]] -> 198.23485 | X8: =Tabela3[[#This Row],[Aluminio Util]]*Tabela3[[#This Row],[Custo/Kg]] -> 706.68 | Y8: =IFERROR(VLOOKUP(Tabela3[[#This Row],[Data]],Tabela461213[],2,1)*(Tabela3[[#This Row],[Qtde Cx Produzida]]*Tabela3[[#This Row],[Qde macho / CX]]*Tabela3[[#This Row],[Peso Macho]]),) -> 0 | Z8: =IFERROR(Tabela3[[#This Row],[Qtde Oleo]]*(VLOOKUP(Tabela3[[#This Row],[Data]],CompraOleo[],3,TRUE))*1.05,0) -> 62.6809 | AA8: =(Tabela3[[#This Row],[Custo Oleo]]+Tabela3[[#This Row],[Custo Aluminio]]+Tabela3[[#This Row],[Custo M.O. Total]]+Tabela3[[#This Row],[Custo Machos]]) -> 967.59575 | AB8: =Tabela3[[#This Row],[Custo Total]]*Tabela3[[#This Row],[% Perda]] -> 0 | AC8: =IFERROR(VLOOKUP(Tabela3[[#This Row],[Produto]],Tabela2[],2,0),0) -> 6 | AD8: =IFERROR(VLOOKUP(Tabela3[[#This Row],[Produto]],Tabela2[],3,0),0) -> 0.302 | AE8: =IFERROR(VLOOKUP(Tabela3[[#This Row],[Produto]],Tabela2[],4,0),0) -> 2.152 | AF8: =IFERROR(VLOOKUP(Tabela3[[#This Row],[Produto]],Tabela2[],5,0),0) -> 0.306 | AG8: =IFERROR(VLOOKUP(Tabela3[[#This Row],[Produto]],Tabela2[],6,0),0) -> 0 | AH8: =IFERROR(VLOOKUP(Tabela3[[#This Row],[Produto]],Tabela2[],7,0),0) -> 0 | AI8: =IFERROR(VLOOKUP(Tabela3[[#This Row],[Produto]],Tabela2[],8,0),0) -> 0 | AJ8: =IFERROR(VLOOKUP(Tabela3[[#This Row],[Produto]],Tabela2[],13,0),0) -> 15.6 | AK8: =IFERROR(VLOOKUP(Tabela3[[#This Row],[Produto]],Tabela2[],14,0),0) -> Senun | AL8: =IFERROR(VLOOKUP(Tabela3[[#This Row],[Produto]],Tabela2[],15,0),0) -> 4 | AM8: =(Tabela3[[#This Row],[Custo Usinagem]]+Tabela3[[#This Row],[Custo / Pç]])*1.2 -> 12.540766 | AN8: =Tabela3[[#This Row],[Valor Mínimo Venda]]*1.15 -> 14.421881 | AO8: =Tabela3[[#This Row],[Tabela 1]]*1.08 -> 15.575631 | AP8: =Tabela3[[#This Row],[Tabela 2]]*1.15 -> 17.911976
A9: 45693 | B9: Prot Câm Dome C Acopl - SENUN METAL | C9: 5309 | D9: Daniel Garcia | E9: Victor Hugo | F9: 82 | G9: 0.36805556 | H9: 25 | I9: =IFERROR(Tabela3[[#This Row],[Custo Total]]/Tabela3[[#This Row],[Aluminio Util]],0) -> 23.653039 | J9: =Tabela3[[#This Row],[Custo Total]]/Tabela3[[#This Row],[Realizado]] -> 7.1432177 | K9: =IFERROR(Tabela3[[#This Row],[Qtde Cx Produzida]]/Tabela3[[#This Row],[Tempo]]/24,0) -> 9.2830189 | L9: =Tabela3[[#This Row],[Qtde Cx Produzida]]*Tabela3[[#This Row],[Qdt Peça Placa]] -> 492 | M9: =Tabela3[[#This Row],[Previsto]]-Tabela3[[#This Row],[Perda Pçs]] -> 467 | N9: =IFERROR(Tabela3[[#This Row],[Perda Pçs]]/Tabela3[[#This Row],[Previsto]],0) -> 0.050813008 | O9: =IFERROR(IF(Tabela3[[#This Row],[Qtde Cx Produzida]] <> 0, Tabela3[[#This Row],[Tempo]] / Tabela3[[#This Row],[Qtde Cx Produzida]], 0),0) -> 0.0044884824 | P9: =IFERROR(Tabela3[[#This Row],[Perda Pçs]]/Tabela3[[#This Row],[Qdt Peça Placa]],0) -> 4.1666667 | Q9: =IFERROR(Tabela3[[#This Row],[Realizado]]*Tabela3[[#This Row],[Peso Util/Pç]],0) -> 141.034 | R9: =IFERROR(Tabela3[[#This Row],[Peso Total Galho]]*Tabela3[[#This Row],[Qtde Cx Produzida]]*1.055,0) -> 186.16952 | S9: =(Tabela3[[#This Row],[Aluminio Bruto]]-Tabela3[[#This Row],[Aluminio Util]])*0.9 -> 40.621968 | T9: =Tabela3[[#This Row],[Aluminio Bruto]]/OleoKGAluminio -> 78.321276 | U9: =IFERROR((VLOOKUP(Tabela3[[#This Row],[Moldador]],Tabela1[],5,)+(VLOOKUP(Tabela3[[#This Row],[Ajudante]],Tabela1[],5,))*3.5),0) -> 99.950346 | V9: =IFERROR(Tabela3[[#This Row],[Custo M.O. / H]]/((Tabela3[[#This Row],[Realizado]]/Tabela3[[#This Row],[Qdt Peça Placa]])/Tabela3[[#This Row],[Tempo]]/24),) -> 11.343401 | W9: =Tabela3[[#This Row],[Custo / Cx Moldada]]*Tabela3[[#This Row],[Qtde Cx Produzida]] -> 930.15889 | X9: =Tabela3[[#This Row],[Aluminio Util]]*Tabela3[[#This Row],[Custo/Kg]] -> 2200.1304 | Y9: =IFERROR(VLOOKUP(Tabela3[[#This Row],[Data]],Tabela461213[],2,1)*(Tabela3[[#This Row],[Qtde Cx Produzida]]*Tabela3[[#This Row],[Qde macho / CX]]*Tabela3[[#This Row],[Peso Macho]]),) -> 0 | Z9: =IFERROR(Tabela3[[#This Row],[Qtde Oleo]]*(VLOOKUP(Tabela3[[#This Row],[Data]],CompraOleo[],3,TRUE))*1.05,0) -> 205.59335 | AA9: =(Tabela3[[#This Row],[Custo Oleo]]+Tabela3[[#This Row],[Custo Aluminio]]+Tabela3[[#This Row],[Custo M.O. Total]]+Tabela3[[#This Row],[Custo Machos]]) -> 3335.8826 | AB9: =Tabela3[[#This Row],[Custo Total]]*Tabela3[[#This Row],[% Perda]] -> 169.50623 | AC9: =IFERROR(VLOOKUP(Tabela3[[#This Row],[Produto]],Tabela2[],2,0),0) -> 6 | AD9: =IFERROR(VLOOKUP(Tabela3[[#This Row],[Produto]],Tabela2[],3,0),0) -> 0.302 | AE9: =IFERROR(VLOOKUP(Tabela3[[#This Row],[Produto]],Tabela2[],4,0),0) -> 2.152 | AF9: =IFERROR(VLOOKUP(Tabela3[[#This Row],[Produto]],Tabela2[],5,0),0) -> 0.306 | AG9: =IFERROR(VLOOKUP(Tabela3[[#This Row],[Produto]],Tabela2[],6,0),0) -> 0 | AH9: =IFERROR(VLOOKUP(Tabela3[[#This Row],[Produto]],Tabela2[],7,0),0) -> 0 | AI9: =IFERROR(VLOOKUP(Tabela3[[#This Row],[Produto]],Tabela2[],8,0),0) -> 0 | AJ9: =IFERROR(VLOOKUP(Tabela3[[#This Row],[Produto]],Tabela2[],13,0),0) -> 15.6 | AK9: =IFERROR(VLOOKUP(Tabela3[[#This Row],[Produto]],Tabela2[],14,0),0) -> Senun | AL9: =IFERROR(VLOOKUP(Tabela3[[#This Row],[Produto]],Tabela2[],15,0),0) -> 4 | AM9: =(Tabela3[[#This Row],[Custo Usinagem]]+Tabela3[[#This Row],[Custo / Pç]])*1.2 -> 13.371861 | AN9: =Tabela3[[#This Row],[Valor Mínimo Venda]]*1.15 -> 15.37764 | AO9: =Tabela3[[#This Row],[Tabela 1]]*1.08 -> 16.607852 | AP9: =Tabela3[[#This Row],[Tabela 2]]*1.15 -> 19.099029
A10: 45694 | B10: Prot Câm Dome C Acopl - SENUN METAL | C10: 5309 | D10: Daniel Garcia | E10: Victor Hugo | F10: 17 | G10: 0.073611111 | H10: 0 | I10: =IFERROR(Tabela3[[#This Row],[Custo Total]]/Tabela3[[#This Row],[Aluminio Util]],0) -> 22.716022 | J10: =Tabela3[[#This Row],[Custo Total]]/Tabela3[[#This Row],[Realizado]] -> 6.8602388 | K10: =IFERROR(Tabela3[[#This Row],[Qtde Cx Produzida]]/Tabela3[[#This Row],[Tempo]]/24,0) -> 9.6226415 | L10: =Tabela3[[#This Row],[Qtde Cx Produzida]]*Tabela3[[#This Row],[Qdt Peça Placa]] -> 102 | M10: =Tabela3[[#This Row],[Previsto]]-Tabela3[[#This Row],[Perda Pçs]] -> 102 | N10: =IFERROR(Tabela3[[#This Row],[Perda Pçs]]/Tabela3[[#This Row],[Previsto]],0) -> 0 | O10: =IFERROR(IF(Tabela3[[#This Row],[Qtde Cx Produzida]] <> 0, Tabela3[[#This Row],[Tempo]] / Tabela3[[#This Row],[Qtde Cx Produzida]], 0),0) -> 0.0043300654 | P10: =IFERROR(Tabela3[[#This Row],[Perda Pçs]]/Tabela3[[#This Row],[Qdt Peça Placa]],0) -> 0 | Q10: =IFERROR(Tabela3[[#This Row],[Realizado]]*Tabela3[[#This Row],[Peso Util/Pç]],0) -> 30.804 | R10: =IFERROR(Tabela3[[#This Row],[Peso Total Galho]]*Tabela3[[#This Row],[Qtde Cx Produzida]]*1.055,0) -> 38.59612 | S10: =(Tabela3[[#This Row],[Aluminio Bruto]]-Tabela3[[#This Row],[Aluminio Util]])*0.9 -> 7.012908 | T10: =Tabela3[[#This Row],[Aluminio Bruto]]/OleoKGAluminio -> 16.237338 | U10: =IFERROR((VLOOKUP(Tabela3[[#This Row],[Moldador]],Tabela1[],5,)+(VLOOKUP(Tabela3[[#This Row],[Ajudante]],Tabela1[],5,))*3.5),0) -> 99.950346 | V10: =IFERROR(Tabela3[[#This Row],[Custo M.O. / H]]/((Tabela3[[#This Row],[Realizado]]/Tabela3[[#This Row],[Qdt Peça Placa]])/Tabela3[[#This Row],[Tempo]]/24),) -> 10.386997 | W10: =Tabela3[[#This Row],[Custo / Cx Moldada]]*Tabela3[[#This Row],[Qtde Cx Produzida]] -> 176.57894 | X10: =Tabela3[[#This Row],[Aluminio Util]]*Tabela3[[#This Row],[Custo/Kg]] -> 480.5424 | Y10: =IFERROR(VLOOKUP(Tabela3[[#This Row],[Data]],Tabela461213[],2,1)*(Tabela3[[#This Row],[Qtde Cx Produzida]]*Tabela3[[#This Row],[Qde macho / CX]]*Tabela3[[#This Row],[Peso Macho]]),) -> 0 | Z10: =IFERROR(Tabela3[[#This Row],[Qtde Oleo]]*(VLOOKUP(Tabela3[[#This Row],[Data]],CompraOleo[],3,TRUE))*1.05,0) -> 42.623012 | AA10: =(Tabela3[[#This Row],[Custo Oleo]]+Tabela3[[#This Row],[Custo Aluminio]]+Tabela3[[#This Row],[Custo M.O. Total]]+Tabela3[[#This Row],[Custo Machos]]) -> 699.74436 | AB10: =Tabela3[[#This Row],[Custo Total]]*Tabela3[[#This Row],[% Perda]] -> 0 | AC10: =IFERROR(VLOOKUP(Tabela3[[#This Row],[Produto]],Tabela2[],2,0),0) -> 6 | AD10: =IFERROR(VLOOKUP(Tabela3[[#This Row],[Produto]],Tabela2[],3,0),0) -> 0.302 | AE10: =IFERROR(VLOOKUP(Tabela3[[#This Row],[Produto]],Tabela2[],4,0),0) -> 2.152 | AF10: =IFERROR(VLOOKUP(Tabela3[[#This Row],[Produto]],Tabela2[],5,0),0) -> 0.306 | AG10: =IFERROR(VLOOKUP(Tabela3[[#This Row],[Produto]],Tabela2[],6,0),0) -> 0 | AH10: =IFERROR(VLOOKUP(Tabela3[[#This Row],[Produto]],Tabela2[],7,0),0) -> 0 | AI10: =IFERROR(VLOOKUP(Tabela3[[#This Row],[Produto]],Tabela2[],8,0),0) -> 0 | AJ10: =IFERROR(VLOOKUP(Tabela3[[#This Row],[Produto]],Tabela2[],13,0),0) -> 15.6 | AK10: =IFERROR(VLOOKUP(Tabela3[[#This Row],[Produto]],Tabela2[],14,0),0) -> Senun | AL10: =IFERROR(VLOOKUP(Tabela3[[#This Row],[Produto]],Tabela2[],15,0),0) -> 4 | AM10: =(Tabela3[[#This Row],[Custo Usinagem]]+Tabela3[[#This Row],[Custo / Pç]])*1.2 -> 13.032287 | AN10: =Tabela3[[#This Row],[Valor Mínimo Venda]]*1.15 -> 14.98713 | AO10: =Tabela3[[#This Row],[Tabela 1]]*1.08 -> 16.1861 | AP10: =Tabela3[[#This Row],[Tabela 2]]*1.15 -> 18.614015
